Workbook

Sheet DVF-3.1-FO05 LEGALIZA
B2: TARJETAS DE CREDITO
B5: FECHA
C7: TOTAL GASTOS PESOS | F7: =SUM(D25:D44) -> 0
C8: TOTAL GASTOS DOLARES | F8: =SUM(E25:E44) -> 0
B11: INFORMACIÓN DEL RESPONSABLE DEL ANTICIPO
B13: NOMBRE:
B15: N. TARJETA
B17: ÁREA:
B19: CARGO:
B23: Fecha | C23: Rubro Programa | D23: Monto COP | E23: Monto USD | F23: NIT | G23: Beneficiario | H23: Detalles | J23: Codigo Contabilidad
J25: =+IFERROR(VLOOKUP(C25,Hoja1!$C$5:$D$54,2,FALSE),"---") -> ---
J26: =+IFERROR(VLOOKUP(C26,Hoja1!$C$5:$D$54,2,FALSE),"---") -> ---
J27: =+IFERROR(VLOOKUP(C27,Hoja1!$C$5:$D$54,2,FALSE),"---") -> ---
J28: =+IFERROR(VLOOKUP(C28,Hoja1!$C$5:$D$54,2,FALSE),"---") -> ---
J29: =+IFERROR(VLOOKUP(C29,Hoja1!$C$5:$D$54,2,FALSE),"---") -> ---
J30: =+IFERROR(VLOOKUP(C30,Hoja1!$C$5:$D$54,2,FALSE),"---") -> ---
J31: =+IFERROR(VLOOKUP(C31,Hoja1!$C$5:$D$54,2,FALSE),"---") -> ---
J32: =+IFERROR(VLOOKUP(C32,Hoja1!$C$5:$D$54,2,FALSE),"---") -> ---
J33: =+IFERROR(VLOOKUP(C33,Hoja1!$C$5:$D$54,2,FALSE),"---") -> ---
J34: =+IFERROR(VLOOKUP(C34,Hoja1!$C$5:$D$54,2,FALSE),"---") -> ---
J35: =+IFERROR(VLOOKUP(C35,Hoja1!$C$5:$D$54,2,FALSE),"---") -> ---
J36: =+IFERROR(VLOOKUP(C36,Hoja1!$C$5:$D$54,2,FALSE),"---") -> ---
... J44: =+IFERROR(VLOOKUP(C44,Hoja1!$C$5:$D$54,2,FALSE),"---") -> ---
C49: Firma
B51: OBSERVACIONES
B82: TRANSPORTE | F82: PESOS COLOMBIANOS | H82: 1 | I82: 2015
B83: HOSPEDAJE | F83: DÓLARES | H83: 2 | I83: 2016
B84: ALIMENTACION | F84: EUROS | H84: 3 | I84: 2017
B85: TARJETA DE TURISMO | H85: 4 | I85: 2018
B86: COSTOS DE VISA | H86: 5 | I86: 2019
B87: GASTO CONSULAR | H87: 6 | I87: 2020
B88: IMPUESTOS MIGRATORIOS | H88: 7 | I88: 2021
B89: SEGURO MEDICO | H89: 8 | I89: 2022
B90: OTROS GASTOS (Resolución Comisiones Univ) | H90: 9 | I90: 2023
B91: COMPRAS DE BIENES Y SERVICIOS-FESTIVAL EVENTOS INSTIT | H91: 10 | I91: 2024
B92: DESTINO MATERIALES Y SUMINISTROS | H92: 11 | I92: 2025
B93: GTOS LEGALES - TRAMITES Y LICENCIAS | H93: 12 | I93: 2026
I94: 2027
I95: 2028
I96: 2029
...

Sheet Hoja1
C4: CENTRO DE COSTO | D4: CODIGO
C5: COORDINACION NACIONAL/Materiales de oficina | D5: 4711
C6: COORDINACION NACIONAL/Otros gastos (Dotacion) | D6: 4712
C7: COORDINACION NACIONAL/Tiquetes aereos | D7: 4721
C8: COORDINACION NACIONAL/Transporte interno | D8: 4722
C9: COORDINACION NACIONAL/Hospedaje | D9: 4723
C10: COORDINACION NACIONAL/Alimentación | D10: 4724
C11: COORDINACION NACIONAL/Tiquete Aereos - asesoria exter | D11: 4731
C12: COORDINACION NACIONAL/Transp Local - asesoria exter | D12: 4732
C13: COORDINACION NACIONAL/Hospedaje - asesoria exter | D13: 4733
C14: COORDINACION NACIONAL/Alimentación - asesoria exter | D14: 4734
C15: COORDINACION NACIONAL/Honorarios - asesoria exter | D15: 4735
... C54: CUBR GASTOS | D54: 2111
