Workbook
Name ADMINISTRACION: Hoja1!#REF!
Name ADMINISTRACION_GENERAL: Hoja1!#REF!
Name ATLANTICO: Hoja1!$L$5:$L$35
Name CALI: Hoja1!$R$5:$R$35
Name CENTROS_ESPECIALES: Hoja1!#REF!
Name CHOCO: Hoja1!$AB$5:$AB$35
Name COORDINACION_ZONA_CENTRO: Hoja1!$AD$5:$AD$24
Name COORDINACION_ZONA_SUR: Hoja1!$AC$5:$AC$25
Name CORDOBA_CENTRAL: Hoja1!$Z$5:$Z$35
Name CUBR_GASTOS: Hoja1!#REF!
Name CULTIVANDO: Hoja1!#REF!
Name ECHIDNA: Hoja1!#REF!
Name LORICA: Hoja1!$AA$5:$AA$35
Name NORTE_DE_ATLANTICO: Hoja1!$N$5:$N$35
Name NORTE_DE_BOLIVAR: Hoja1!$J$5:$J$35
Name NORTE_DE_CAUCA: Hoja1!$S$5:$S$35
Name NORTE_DE_CORDOBA: Hoja1!$X$5:$X$35
Name ORIENTE_DE_SUCRE: Hoja1!$V$5:$V$35
Name PAS_COORDINACION_NACIONAL: Hoja1!$I$5:$I$19
Name RIOFRIO_Y_TULUA: Hoja1!$O$5:$O$35
Name RIOHACHA: Hoja1!$U$5:$U$35
Name RUBRO: Hoja1!$D$5:$D$19
Name SAN_SEBASTIAN: Hoja1!$Y$5:$Y$35
Name SANTA_LUCIA: Hoja1!$M$5:$M$35
Name SANTA_ROSA: Hoja1!$K$5:$K$35
Name SUCRE_CENTRAL: Hoja1!$W$5:$W$35
Name SUR_GUAJIRA: Hoja1!$P$5:$P$35
Name VALLEDUPAR: Hoja1!$Q$5:$Q$35
Name YARUMALES_PADILLA_PAILA: Hoja1!$T$5:$T$35

Sheet DVF-3.1-FO05 LEGALIZA
B2: LEGALIZACION DE ANTICIPO
B5: FECHA
D7: TOTAL GASTOS | F7: =SUM(E25:E45) -> 0
D8: VALOR ANTICIPO | F8: 0
D9: VALOR A REINTEGRAR | E9: SI | F9: =F8-F7 -> 0
B11: INFORMACIÓN DEL RESPONSABLE DEL ANTICIPO
B13: NOMBRE: | G13: CONCEPTO DE LEGALIZACIÓN:
B15: CC.
B17: ÁREA:
B19: CARGO:
B23: Fecha | C23: Centro de Costos | D23: Rubro Programa | E23: Monto COP | F23: NIT | G23: Beneficiario | H23: Detalles | J23: Codigo Contabilidad
J25: =IFERROR(CONCATENATE(VLOOKUP(C25,Hoja1!$B$4:$C$78,2,FALSE),VLOOKUP(D25,Hoja1!$D$4:$E$78,2,FALSE)),"---") -> ---
J26: =IFERROR(CONCATENATE(VLOOKUP(C26,Hoja1!$B$4:$C$78,2,FALSE),VLOOKUP(D26,Hoja1!$D$4:$E$78,2,FALSE)),"---") -> ---
J27: =IFERROR(CONCATENATE(VLOOKUP(C27,Hoja1!$B$4:$C$78,2,FALSE),VLOOKUP(D27,Hoja1!$D$4:$E$78,2,FALSE)),"---") -> ---
J28: =IFERROR(CONCATENATE(VLOOKUP(C28,Hoja1!$B$4:$C$78,2,FALSE),VLOOKUP(D28,Hoja1!$D$4:$E$78,2,FALSE)),"---") -> ---
J29: =IFERROR(CONCATENATE(VLOOKUP(C29,Hoja1!$B$4:$C$78,2,FALSE),VLOOKUP(D29,Hoja1!$D$4:$E$78,2,FALSE)),"---") -> ---
J30: =IFERROR(CONCATENATE(VLOOKUP(C30,Hoja1!$B$4:$C$78,2,FALSE),VLOOKUP(D30,Hoja1!$D$4:$E$78,2,FALSE)),"---") -> ---
J31: =IFERROR(CONCATENATE(VLOOKUP(C31,Hoja1!$B$4:$C$78,2,FALSE),VLOOKUP(D31,Hoja1!$D$4:$E$78,2,FALSE)),"---") -> ---
J32: =IFERROR(CONCATENATE(VLOOKUP(C32,Hoja1!$B$4:$C$78,2,FALSE),VLOOKUP(D32,Hoja1!$D$4:$E$78,2,FALSE)),"---") -> ---
J33: =IFERROR(CONCATENATE(VLOOKUP(C33,Hoja1!$B$4:$C$78,2,FALSE),VLOOKUP(D33,Hoja1!$D$4:$E$78,2,FALSE)),"---") -> ---
J34: =IFERROR(CONCATENATE(VLOOKUP(C34,Hoja1!$B$4:$C$78,2,FALSE),VLOOKUP(D34,Hoja1!$D$4:$E$78,2,FALSE)),"---") -> ---
J35: =IFERROR(CONCATENATE(VLOOKUP(C35,Hoja1!$B$4:$C$78,2,FALSE),VLOOKUP(D35,Hoja1!$D$4:$E$78,2,FALSE)),"---") -> ---
J36: =IFERROR(CONCATENATE(VLOOKUP(C36,Hoja1!$B$4:$C$78,2,FALSE),VLOOKUP(D36,Hoja1!$D$4:$E$78,2,FALSE)),"---") -> ---
... J45: =IFERROR(CONCATENATE(VLOOKUP(C45,Hoja1!$B$4:$C$78,2,FALSE),VLOOKUP(D45,Hoja1!$D$4:$E$78,2,FALSE)),"---") -> ---
D50: Firma
B52: OBSERVACIONES
B83: TRANSPORTE | F83: PESOS COLOMBIANOS | H83: 1 | I83: 2015
B84: HOSPEDAJE | F84: DÓLARES | H84: 2 | I84: 2016
B85: ALIMENTACION | F85: EUROS | H85: 3 | I85: 2017
B86: TARJETA DE TURISMO | H86: 4 | I86: 2018
B87: COSTOS DE VISA | H87: 5 | I87: 2019
B88: GASTO CONSULAR | H88: 6 | I88: 2020
B89: IMPUESTOS MIGRATORIOS | H89: 7 | I89: 2021
B90: SEGURO MEDICO | H90: 8 | I90: 2022
B91: OTROS GASTOS (Resolución Comisiones Univ) | H91: 9 | I91: 2023
B92: COMPRAS DE BIENES Y SERVICIOS-FESTIVAL EVENTOS INSTIT | H92: 10 | I92: 2024
B93: DESTINO MATERIALES Y SUMINISTROS | H93: 11 | I93: 2025
B94: GTOS LEGALES - TRAMITES Y LICENCIAS | H94: 12 | I94: 2026
I95: 2027
I96: 2028
...

Sheet Hoja1
B4: CENTRO DE COSTO | C4: CODIGO | D4: Rubro Programa | E4: CODIGO | I4: PAS COORDINACION NACIONAL | J4: NORTE DE BOLIVAR | K4: SANTA ROSA | L4: ATLANTICO | M4: SANTA LUCIA | N4: NORTE DE ATLANTICO | O4: RIOFRIO Y TULUA | P4: SUR GUAJIRA | Q4: VALLEDUPAR | R4: CALI | S4: NORTE DE CAUCA | T4: YARUMALES PADILLA PAILA | U4: RIOHACHA | V4: ORIENTE DE SUCRE | W4: SUCRE CENTRAL | X4: NORTE DE CORDOBA | Y4: SAN SEBASTIAN | Z4: CORDOBA CENTRAL | AA4: LORICA | AB4: CHOCO | AC4: COORDINACION ZONA SUR | AD4: COORDINACION ZONA CENTRO
B5: PAS COORDINACION NACIONAL | C5: 47 | D5: Materiales de oficina | E5: 11 | I5: Materiales de oficina | J5: Teléfono | K5: Teléfono | L5: Teléfono | M5: Teléfono | N5: Teléfono | O5: Teléfono | P5: Teléfono | Q5: Teléfono | R5: Teléfono | S5: Teléfono | T5: Teléfono | U5: Teléfono | V5: Teléfono | W5: Teléfono | X5: Teléfono | Y5: Teléfono | Z5: Teléfono | AA5: Teléfono | AB5: Teléfono | AC5: Teléfono | AD5: Teléfono
B6: PAS COORDINACION NACIONAL | C6: 47 | D6: Otros gastos (Dotacion) | E6: 12 | I6: Otros gastos (Dotacion) | J6: Internet | K6: Internet | L6: Internet | M6: Internet | N6: Internet | O6: Internet | P6: Internet | Q6: Internet | R6: Internet | S6: Internet | T6: Internet | U6: Internet | V6: Internet | W6: Internet | X6: Internet | Y6: Internet | Z6: Internet | AA6: Internet | AB6: Internet | AC6: Internet | AD6: Internet
B7: PAS COORDINACION NACIONAL | C7: 47 | D7: Tiquetes aereos | E7: 21 | I7: Tiquetes aereos | J7: Materiales de Oficina | K7: Materiales de Oficina | L7: Materiales de Oficina | M7: Materiales de Oficina | N7: Materiales de Oficina | O7: Materiales de Oficina | P7: Materiales de Oficina | Q7: Materiales de Oficina | R7: Materiales de Oficina | S7: Materiales de Oficina | T7: Materiales de Oficina | U7: Materiales de Oficina | V7: Materiales de Oficina | W7: Materiales de Oficina | X7: Materiales de Oficina | Y7: Materiales de Oficina | Z7: Materiales de Oficina | AA7: Materiales de Oficina | AB7: Materiales de Oficina | AC7: Materiales de Oficina | AD7: Materiales de Oficina
B8: PAS COORDINACION NACIONAL | C8: 47 | D8: Transporte interno | E8: 22 | I8: Transporte interno | J8: Correo/Transporte de Materiales | K8: Correo/Transporte de Materiales | L8: Correo/Transporte de Materiales | M8: Correo/Transporte de Materiales | N8: Correo/Transporte de Materiales | O8: Correo/Transporte de Materiales | P8: Correo/Transporte de Materiales | Q8: Correo/Transporte de Materiales | R8: Correo/Transporte de Materiales | S8: Correo/Transporte de Materiales | T8: Correo/Transporte de Materiales | U8: Correo/Transporte de Materiales | V8: Correo/Transporte de Materiales | W8: Correo/Transporte de Materiales | X8: Correo/Transporte de Materiales | Y8: Correo/Transporte de Materiales | Z8: Correo/Transporte de Materiales | AA8: Correo/Transporte de Materiales | AB8: Correo/Transporte de Materiales | AC8: Correo/Transporte de Materiales | AD8: Correo/Transporte de Materiales
B9: PAS COORDINACION NACIONAL | C9: 47 | D9: Hospedaje | E9: 23 | I9: Hospedaje | J9: Muebles y computadores | K9: Muebles y computadores | L9: Muebles y computadores | M9: Muebles y computadores | N9: Muebles y computadores | O9: Muebles y computadores | P9: Muebles y computadores | Q9: Muebles y computadores | R9: Muebles y computadores | S9: Muebles y computadores | T9: Muebles y computadores | U9: Muebles y computadores | V9: Muebles y computadores | W9: Muebles y computadores | X9: Muebles y computadores | Y9: Muebles y computadores | Z9: Muebles y computadores | AA9: Muebles y computadores | AB9: Muebles y computadores | AC9: Muebles y computadores | AD9: Muebles y computadores
B10: PAS COORDINACION NACIONAL | C10: 47 | D10: Alimentación | E10: 24 | I10: Alimentación | J10: Arriendo | K10: Arriendo | L10: Arriendo | M10: Arriendo | N10: Arriendo | O10: Arriendo | P10: Arriendo | Q10: Arriendo | R10: Arriendo | S10: Arriendo | T10: Arriendo | U10: Arriendo | V10: Arriendo | W10: Arriendo | X10: Arriendo | Y10: Arriendo | Z10: Arriendo | AA10: Arriendo | AB10: Arriendo | AC10: Arriendo | AD10: Arriendo
B11: PAS COORDINACION NACIONAL | C11: 47 | D11: Tiquete Aereos - asesoria exter | E11: 31 | I11: Tiquete Aereos - asesoria exter | J11: Transporte | K11: Transporte | L11: Transporte | M11: Transporte | N11: Transporte | O11: Transporte | P11: Transporte | Q11: Transporte | R11: Transporte | S11: Transporte | T11: Transporte | U11: Transporte | V11: Transporte | W11: Transporte | X11: Transporte | Y11: Transporte | Z11: Transporte | AA11: Transporte | AB11: Transporte | AC11: Transporte | AD11: Transporte
B12: PAS COORDINACION NACIONAL | C12: 47 | D12: Transp Local - asesoria exter | E12: 32 | I12: Transp Local - asesoria exter | J12: Otros Gastos (Dotación) | K12: Otros Gastos (Dotación) | L12: Otros Gastos (Dotación) | M12: Otros Gastos (Dotación) | N12: Otros Gastos (Dotación) | O12: Otros Gastos (Dotación) | P12: Otros Gastos (Dotación) | Q12: Otros Gastos (Dotación) | R12: Otros Gastos (Dotación) | S12: Otros Gastos (Dotación) | T12: Otros Gastos (Dotación) | U12: Otros Gastos (Dotación) | V12: Otros Gastos (Dotación) | W12: Otros Gastos (Dotación) | X12: Otros Gastos (Dotación) | Y12: Otros Gastos (Dotación) | Z12: Otros Gastos (Dotación) | AA12: Otros Gastos (Dotación) | AB12: Otros Gastos (Dotación) | AC12: Otros Gastos (Dotación y Gastos Bancarios) | AD12: Otros Gastos (Dotación y Gastos Bancarios)
B13: PAS COORDINACION NACIONAL | C13: 47 | D13: Hospedaje - asesoria exter | E13: 33 | I13: Hospedaje - asesoria exter | J13: Laboratorio | K13: Laboratorio | L13: Laboratorio | M13: Laboratorio | N13: Laboratorio | O13: Laboratorio | P13: Laboratorio | Q13: Laboratorio | R13: Laboratorio | S13: Laboratorio | T13: Laboratorio | U13: Laboratorio | V13: Laboratorio | W13: Laboratorio | X13: Laboratorio | Y13: Laboratorio | Z13: Laboratorio | AA13: Laboratorio | AB13: Laboratorio | AC13: Encuentro nacional de coordinadores | AD13: Encuentro nacional de coordinadores
B14: PAS COORDINACION NACIONAL | C14: 47 | D14: Alimentación - asesoria exter | E14: 34 | I14: Alimentación - asesoria exter | J14: Textos | K14: Textos | L14: Textos | M14: Textos | N14: Textos | O14: Textos | P14: Textos | Q14: Textos | R14: Textos | S14: Textos | T14: Textos | U14: Textos | V14: Textos | W14: Textos | X14: Textos | Y14: Textos | Z14: Textos | AA14: Textos | AB14: Textos | AC14: Encuentro regional de coordinadores | AD14: Encuentro regional de coordinadores
B15: PAS COORDINACION NACIONAL | C15: 47 | D15: Honorarios - asesoria exter | E15: 35 | I15: Honorarios - asesoria exter | J15: Materiales Prácticas | K15: Materiales Prácticas | L15: Materiales Prácticas | M15: Materiales Prácticas | N15: Materiales Prácticas | O15: Materiales Prácticas | P15: Materiales Prácticas | Q15: Materiales Prácticas | R15: Materiales Prácticas | S15: Materiales Prácticas | T15: Materiales Prácticas | U15: Materiales Prácticas | V15: Materiales Prácticas | W15: Materiales Prácticas | X15: Materiales Prácticas | Y15: Materiales Prácticas | Z15: Materiales Prácticas | AA15: Materiales Prácticas | AB15: Materiales Prácticas | AC15: Capacitación de capacitadores | AD15: Capacitación de capacitadores
B16: PAS COORDINACION NACIONAL | C16: 47 | D16: Encuentro Nacional | E16: 41 | I16: Encuentro Nacional | J16: Encuentro nacional de coordinadores | K16: Encuentro nacional de coordinadores | L16: Encuentro nacional de coordinadores | M16: Encuentro nacional de coordinadores | N16: Encuentro nacional de coordinadores | O16: Encuentro nacional de coordinadores | P16: Encuentro nacional de coordinadores | Q16: Encuentro nacional de coordinadores | R16: Encuentro nacional de coordinadores | S16: Encuentro nacional de coordinadores | T16: Encuentro nacional de coordinadores | U16: Encuentro nacional de coordinadores | V16: Encuentro nacional de coordinadores | W16: Encuentro nacional de coordinadores | X16: Encuentro nacional de coordinadores | Y16: Encuentro nacional de coordinadores | Z16: Encuentro nacional de coordinadores | AA16: Encuentro nacional de coordinadores | AB16: Encuentro nacional de coordinadores | AC16: Capacitación de tutores en documentos | AD16: Capacitación de tutores en documentos
... B19: PAS COORDINACION NACIONAL | C19: 47 | D19: Pasantía | E19: 61 | I19: Pasantía | J19: Encuentros de participantes | K19: Encuentros de participantes | L19: Encuentros de participantes | M19: Encuentros de participantes | N19: Encuentros de participantes | O19: Encuentros de participantes | P19: Encuentros de participantes | Q19: Encuentros de participantes | R19: Encuentros de participantes | S19: Encuentros de participantes | T19: Encuentros de participantes | U19: Encuentros de participantes | V19: Encuentros de participantes | W19: Encuentros de participantes | X19: Encuentros de participantes | Y19: Encuentros de participantes | Z19: Encuentros de participantes | AA19: Encuentros de participantes | AB19: Encuentros de participantes | AC19: Reuniones zonales | AD19: Reuniones zonales
B20: NORTE DE BOLIVAR | C20: 411 | D20: Teléfono | E20: 11 | J20: Encuentros de Tutores | K20: Encuentros de Tutores | L20: Encuentros de Tutores | M20: Encuentros de Tutores | N20: Encuentros de Tutores | O20: Encuentros de Tutores | P20: Encuentros de Tutores | Q20: Encuentros de Tutores | R20: Encuentros de Tutores | S20: Encuentros de Tutores | T20: Encuentros de Tutores | U20: Encuentros de Tutores | V20: Encuentros de Tutores | W20: Encuentros de Tutores | X20: Encuentros de Tutores | Y20: Encuentros de Tutores | Z20: Encuentros de Tutores | AA20: Encuentros de Tutores | AB20: Encuentros de Tutores | AC20: Fondo semilla | AD20: Fondo semilla
B21: SANTA ROSA | C21: 412 | D21: Internet | E21: 12 | J21: Reunion Refuerzo y Avance | K21: Reunion Refuerzo y Avance | L21: Reunion Refuerzo y Avance | M21: Reunion Refuerzo y Avance | N21: Reunion Refuerzo y Avance | O21: Reunion Refuerzo y Avance | P21: Reunion Refuerzo y Avance | Q21: Reunion Refuerzo y Avance | R21: Reunion Refuerzo y Avance | S21: Reunion Refuerzo y Avance | T21: Reunion Refuerzo y Avance | U21: Reunion Refuerzo y Avance | V21: Reunion Refuerzo y Avance | W21: Reunion Refuerzo y Avance | X21: Reunion Refuerzo y Avance | Y21: Reunion Refuerzo y Avance | Z21: Reunion Refuerzo y Avance | AA21: Reunion Refuerzo y Avance | AB21: Reunion Refuerzo y Avance | AC21: Proyectos de servicio | AD21: Proyectos de servicio
B22: ATLANTICO | C22: 413 | D22: Materiales de Oficina | E22: 13 | J22: Costos de transporte y tutorias | K22: Costos de transporte y tutorias | L22: Costos de transporte y tutorias | M22: Costos de transporte y tutorias | N22: Costos de transporte y tutorias | O22: Costos de transporte y tutorias | P22: Costos de transporte y tutorias | Q22: Costos de transporte y tutorias | R22: Costos de transporte y tutorias | S22: Costos de transporte y tutorias | T22: Costos de transporte y tutorias | U22: Costos de transporte y tutorias | V22: Costos de transporte y tutorias | W22: Costos de transporte y tutorias | X22: Costos de transporte y tutorias | Y22: Costos de transporte y tutorias | Z22: Costos de transporte y tutorias | AA22: Costos de transporte y tutorias | AB22: Costos de transporte y tutorias | AC22: Capacitación y asesoría administrativa | AD22: Capacitación y asesoría administrativa
B23: SANTA LUCIA | C23: 414 | D23: Correo/Transporte de Materiales | E23: 14 | J23: Reuniones Coordinador con Asistentes | K23: Reuniones Coordinador con Asistentes | L23: Reuniones Coordinador con Asistentes | M23: Reuniones Coordinador con Asistentes | N23: Reuniones Coordinador con Asistentes | O23: Reuniones Coordinador con Asistentes | P23: Reuniones Coordinador con Asistentes | Q23: Reuniones Coordinador con Asistentes | R23: Reuniones Coordinador con Asistentes | S23: Reuniones Coordinador con Asistentes | T23: Reuniones Coordinador con Asistentes | U23: Reuniones Coordinador con Asistentes | V23: Reuniones Coordinador con Asistentes | W23: Reuniones Coordinador con Asistentes | X23: Reuniones Coordinador con Asistentes | Y23: Reuniones Coordinador con Asistentes | Z23: Reuniones Coordinador con Asistentes | AA23: Reuniones Coordinador con Asistentes | AB23: Reuniones Coordinador con Asistentes | AC23: Personal auxiliar | AD23: Personal auxiliar
B24: NORTE DE ATLANTICO | C24: 415 | D24: Muebles y computadores | E24: 15 | J24: Reuniones Interinstitucionales | K24: Reuniones Interinstitucionales | L24: Reuniones Interinstitucionales | M24: Reuniones Interinstitucionales | N24: Reuniones Interinstitucionales | O24: Reuniones Interinstitucionales | P24: Reuniones Interinstitucionales | Q24: Reuniones Interinstitucionales | R24: Reuniones Interinstitucionales | S24: Reuniones Interinstitucionales | T24: Reuniones Interinstitucionales | U24: Reuniones Interinstitucionales | V24: Reuniones Interinstitucionales | W24: Reuniones Interinstitucionales | X24: Reuniones Interinstitucionales | Y24: Reuniones Interinstitucionales | Z24: Reuniones Interinstitucionales | AA24: Reuniones Interinstitucionales | AB24: Reuniones Interinstitucionales | AC24: Personal coordinación | AD24: Personal coordinación
B25: RIOFRIO/TULUA | C25: 421 | D25: Arriendo | E25: 16 | J25: Reuniones con otras organizaciones | K25: Reuniones con otras organizaciones | L25: Reuniones con otras organizaciones | M25: Reuniones con otras organizaciones | N25: Reuniones con otras organizaciones | O25: Reuniones con otras organizaciones | P25: Reuniones con otras organizaciones | Q25: Reuniones con otras organizaciones | R25: Reuniones con otras organizaciones | S25: Reuniones con otras organizaciones | T25: Reuniones con otras organizaciones | U25: Reuniones con otras organizaciones | V25: Reuniones con otras organizaciones | W25: Reuniones con otras organizaciones | X25: Reuniones con otras organizaciones | Y25: Reuniones con otras organizaciones | Z25: Reuniones con otras organizaciones | AA25: Reuniones con otras organizaciones | AB25: Reuniones con otras organizaciones | AC25: Costos Administrativos FEDESSCO
B26: SUR GUAJIRA | C26: 431 | D26: Transporte | E26: 17 | J26: Parcelas demostrativas | K26: Parcelas demostrativas | L26: Parcelas demostrativas | M26: Parcelas demostrativas | N26: Parcelas demostrativas | O26: Parcelas demostrativas | P26: Parcelas demostrativas | Q26: Parcelas demostrativas | R26: Parcelas demostrativas | S26: Parcelas demostrativas | T26: Parcelas demostrativas | U26: Parcelas demostrativas | V26: Parcelas demostrativas | W26: Parcelas demostrativas | X26: Parcelas demostrativas | Y26: Parcelas demostrativas | Z26: Parcelas demostrativas | AA26: Parcelas demostrativas | AB26: Parcelas demostrativas
B27: VALLEDUPAR | C27: 432 | D27: Otros Gastos (Dotación) | E27: 18 | J27: Proyectos de servicio | K27: Proyectos de servicio | L27: Proyectos de servicio | M27: Proyectos de servicio | N27: Proyectos de servicio | O27: Proyectos de servicio | P27: Proyectos de servicio | Q27: Proyectos de servicio | R27: Proyectos de servicio | S27: Proyectos de servicio | T27: Proyectos de servicio | U27: Proyectos de servicio | V27: Proyectos de servicio | W27: Proyectos de servicio | X27: Proyectos de servicio | Y27: Proyectos de servicio | Z27: Proyectos de servicio | AA27: Proyectos de servicio | AB27: Proyectos de servicio
B28: CALI | C28: 441 | D28: Laboratorio | E28: 51 | J28: Iniciativas productivas | K28: Iniciativas productivas | L28: Iniciativas productivas | M28: Iniciativas productivas | N28: Iniciativas productivas | O28: Iniciativas productivas | P28: Iniciativas productivas | Q28: Iniciativas productivas | R28: Iniciativas productivas | S28: Iniciativas productivas | T28: Iniciativas productivas | U28: Iniciativas productivas | V28: Iniciativas productivas | W28: Iniciativas productivas | X28: Iniciativas productivas | Y28: Iniciativas productivas | Z28: Iniciativas productivas | AA28: Iniciativas productivas | AB28: Iniciativas productivas
B29: NORTE DE CAUCA | C29: 451 | D29: Textos | E29: 52 | J29: Personal tutoria | K29: Personal tutoria | L29: Personal tutoria | M29: Personal tutoria | N29: Personal tutoria | O29: Personal tutoria | P29: Personal tutoria | Q29: Personal tutoria | R29: Personal tutoria | S29: Personal tutoria | T29: Personal tutoria | U29: Personal tutoria | V29: Personal tutoria | W29: Personal tutoria | X29: Personal tutoria | Y29: Personal tutoria | Z29: Personal tutoria | AA29: Personal tutoria | AB29: Personal tutoria
B30: YARUMALES-PADILLA-PAILA | C30: 452 | D30: Materiales Prácticas | E30: 53 | J30: Personal pasantia | K30: Personal pasantia | L30: Personal pasantia | M30: Personal pasantia | N30: Personal pasantia | O30: Personal pasantia | P30: Personal pasantia | Q30: Personal pasantia | R30: Personal pasantia | S30: Personal pasantia | T30: Personal pasantia | U30: Personal pasantia | V30: Personal pasantia | W30: Personal pasantia | X30: Personal pasantia | Y30: Personal pasantia | Z30: Personal pasantia | AA30: Personal pasantia | AB30: Personal pasantia
B31: RIOHACHA | C31: 461 | D31: Encuentro nacional de coordinadores | E31: 21 | J31: Personal coordinación | K31: Personal coordinación | L31: Personal coordinación | M31: Personal coordinación | N31: Personal coordinación | O31: Personal coordinación | P31: Personal coordinación | Q31: Personal coordinación | R31: Personal coordinación | S31: Personal coordinación | T31: Personal coordinación | U31: Personal coordinación | V31: Personal coordinación | W31: Personal coordinación | X31: Personal coordinación | Y31: Personal coordinación | Z31: Personal coordinación | AA31: Personal coordinación | AB31: Personal coordinación
B32: ORIENTE DE SUCRE | C32: 511 | D32: Encuentro regional de coordinadores | E32: 22 | J32: Personal asistente | K32: Personal asistente | L32: Personal asistente | M32: Personal asistente | N32: Personal asistente | O32: Personal asistente | P32: Personal asistente | Q32: Personal asistente | R32: Personal asistente | S32: Personal asistente | T32: Personal asistente | U32: Personal asistente | V32: Personal asistente | W32: Personal asistente | X32: Personal asistente | Y32: Personal asistente | Z32: Personal asistente | AA32: Personal asistente | AB32: Personal asistente
B33: SUCRE CENTRAL | C33: 512 | D33: Costos locales de capacitación | E33: 23 | J33: Apoyo financiero/Becas/ Oficios | K33: Apoyo financiero/Becas/ Oficios | L33: Apoyo financiero/Becas/ Oficios | M33: Apoyo financiero/Becas/ Oficios | N33: Apoyo financiero/Becas/ Oficios | O33: Apoyo financiero/Becas/ Oficios | P33: Apoyo financiero/Becas/ Oficios | Q33: Apoyo financiero/Becas/ Oficios | R33: Apoyo financiero/Becas/ Oficios | S33: Apoyo financiero/Becas/ Oficios | T33: Apoyo financiero/Becas/ Oficios | U33: Apoyo financiero/Becas/ Oficios | V33: Apoyo financiero/Becas/ Oficios | W33: Apoyo financiero/Becas/ Oficios | X33: Apoyo financiero/Becas/ Oficios | Y33: Apoyo financiero/Becas/ Oficios | Z33: Apoyo financiero/Becas/ Oficios | AA33: Apoyo financiero/Becas/ Oficios | AB33: Apoyo financiero/Becas/ Oficios
B34: NORTE DE CORDOBA | C34: 513 | D34: Encuentros de participantes | E34: 24 | J34: Capacitación: ISGP - Cursos cortos | K34: Capacitación: ISGP - Cursos cortos | L34: Capacitación: ISGP - Cursos cortos | M34: Capacitación: ISGP - Cursos cortos | N34: Capacitación: ISGP - Cursos cortos | O34: Capacitación: ISGP - Cursos cortos | P34: Capacitación: ISGP - Cursos cortos | Q34: Capacitación: ISGP - Cursos cortos | R34: Capacitación: ISGP - Cursos cortos | S34: Capacitación: ISGP - Cursos cortos | T34: Capacitación: ISGP - Cursos cortos | U34: Capacitación: ISGP - Cursos cortos | V34: Capacitación: ISGP - Cursos cortos | W34: Capacitación: ISGP - Cursos cortos | X34: Capacitación: ISGP - Cursos cortos | Y34: Capacitación: ISGP - Cursos cortos | Z34: Capacitación: ISGP - Cursos cortos | AA34: Capacitación: ISGP - Cursos cortos | AB34: Capacitación: ISGP - Cursos cortos
B35: SAN SEBASTIAN | C35: 514 | D35: Encuentros de Tutores | E35: 25 | J35: Encuentros | K35: Encuentros | L35: Encuentros | M35: Encuentros | N35: Encuentros | O35: Encuentros | P35: Encuentros | Q35: Encuentros | R35: Encuentros | S35: Encuentros | T35: Encuentros | U35: Encuentros | V35: Encuentros | W35: Encuentros | X35: Encuentros | Y35: Encuentros | Z35: Encuentros | AA35: Encuentros | AB35: Encuentros
B36: CORDOBA CENTRAL | C36: 515 | D36: Reunion Refuerzo y Avance | E36: 26
B37: LORICA | C37: 516 | D37: Costos de transporte y tutorias | E37: 27
B38: CHOCO | C38: 481 | D38: Reuniones Coordinador con Asistentes | E38: 28
B39: COORDINACION ZONA SUR | C39: 517 | D39: Reuniones Interinstitucionales | E39: 29
B40: COORDINACION ZONA CENTRO | C40: 416 | D40: Reuniones con otras organizaciones | E40: 31
D41: Parcelas demostrativas | E41: 32
D42: Proyectos de servicio | E42: 34
D43: Iniciativas productivas | E43: 33
D44: Personal tutoria | E44: 41
D45: Personal pasantia | E45: 43
...
